Workbook

Sheet Leeme
A1: KeyServ — Seguimiento del proyecto
A3: Para qué sirve | B3: Un solo lugar para no perder nada: qué falta (Tareas), qué cambió (Cambios), qué se decidió (Decisiones), qué depende de ti (Pendientes_dueño), qué puede salir mal (Riesgos), cuánto cuesta (Presupuesto, Comision) y cómo probarlo (Pruebas).
A4: Cómo usarlo | B4: Cada vez que se agregue o cambie algo: 1) una fila en Cambios (o corre el paso del README), 2) actualiza el Estado de la tarea en Tareas, 3) si fue una decisión, una fila en Decisiones. La fuente de verdad del código es git; esto es el tablero.
A5: Colores | B5: Texto azul = dato que tú puedes cambiar. Celda amarilla = falta que la completes. Negro = fórmula o texto fijo. Los estados se pintan solos: Hecho (verde), En curso (amarillo), Bloqueado (rojo).
A6: Planner | B6: La hoja "Planner" ya trae las columnas que usa Microsoft Planner (Título, Bucket, Progreso, Prioridad, Fecha límite, Asignado, Notas) y se llena sola desde Tareas. Cópiala y pégala en Planner, o súbela a Excel Online/Teams y conéctala con Power Automate.
A7: Hojas | B7: Tareas · Planner · Cambios · Decisiones · Pendientes_dueño · Riesgos · Comision (calculadora con fórmulas) · Presupuesto · Pruebas · Corfo (requisitos de las bases) · Gantt (10 meses de ejecución)
A8: Repositorio | B8: Docs en docs/ (índice en docs/README.md). Estado de la sesión: docs/ESTADO_Y_PROXIMOS_PASOS.md. Seguimiento: docs/seguimiento/README.md.
A9: Última actualización | B9: Generado el 2026-10-16 a partir del repositorio (hoja Cambios sale de git log).

Sheet Tareas
A1: ID | B1: Área | C1: Tarea | D1: Prioridad | E1: Estado | F1: Responsable | G1: Depende de | H1: Fecha límite | I1: Notas | J1: Referencia
A2: T-001 | B2: Cuentas y claves | C2: Crear cuenta SMTP (Gmail/Outlook/Brevo) y cargar SMTP_* y DJANGO_DEFAULT_FROM_EMAIL en .env y en Render; probar con probar_correo | D2: Alta | E2: Pendiente | F2: Dueño | I2: Desbloquea recuperar clave, códigos por correo y todos los avisos | J2: ESTADO_Y_PROXIMOS_PASOS.md
A3: T-002 | B3: Cuentas y claves | C3: Crear cuenta de pruebas en sandbox.flow.cl y cargar FLOW_API_KEY, FLOW_SECRET_KEY, FLOW_AMBIENTE | D3: Alta | E3: Pendiente | F3: Dueño | I3: Escribirlas tú, nunca en el chat | J3: ESTADO_Y_PROXIMOS_PASOS.md
A4: T-003 | B4: Cuentas y claves | C4: Crear aplicación en Mercado Pago Chile y cargar MERCADOPAGO_ACCESS_TOKEN de prueba (TEST-...) | D4: Alta | E4: Pendiente | F4: Dueño | I4: Sus notificaciones exigen URL pública https: probar contra Render | J4: ESTADO_Y_PROXIMOS_PASOS.md
A5: T-004 | B5: Cuentas y claves | C5: Fijar en Render DJANGO_SECRET_KEY, JWT_SECRET y BIOMETRIC_ENCRYPTION_KEYS (hoy usan valores por defecto) | D5: Media | E5: Pendiente | F5: Dueño | I5: Cambiar JWT_SECRET cierra la sesión de todos; BIOMETRIC_* exige rotar antes (rotar_llaves_biometricas) | J5: docs/cumplimiento/rotacion-de-llaves.md
A6: T-005 | B6: Cuentas y claves | C6: Respaldar keyserv-release.keystore y keystore.properties fuera del repo | D6: Media | E6: Pendiente | F6: Dueño | I6: Perderlos = no poder actualizar la app en Play Store | J6: CLAUDE.md
A7: T-006 | B7: Cuentas y claves | C7: Revisar términos del API gratuito de NVIDIA para producción y declarar el envío de texto fuera de Chile | D7: Media | E7: Pendiente | F7: Dueño | J7: docs/adr/0005
A8: T-007 | B8: Legal | C8: Revisión de un abogado: consentimiento biométrico, video de verificación, EIPD, qué se conserva al eliminar cuenta, evidencia para investigaciones | D8: Alta | E8: Pendiente | F8: Dueño | I8: Ver preguntas en ADR 0007 | J8: docs/adr/0007
A9: T-008 | B9: Legal | C9: Redactar Términos y Condiciones (quién responde por el servicio, reembolsos, disputas, comisión) | D9: Alta | E9: Pendiente | F9: Dueño | G9: Abogado | I9: Hoy no existen | J9: PLAN_FLUJO_DE_DINERO.md
A10: T-009 | B10: Legal | C10: Consultar si custodiar fondos de terceros cae bajo la Ley Fintech 21.521 | D10: Alta | E10: Pendiente | F10: Dueño | G10: Abogado | I10: Pregunta de mayor riesgo del plan de dinero | J10: PLAN_FLUJO_DE_DINERO.md
A11: T-010 | B11: Negocio | C11: Contador: IVA de la comisión, boleta/factura, retenciones, régimen para iniciar actividades | D11: Alta | E11: Pendiente | F11: Dueño | J11: PLAN_FLUJO_DE_DINERO.md
A12: T-011 | B12: Negocio | C12: Decidir la comisión final (tramos, mínimo, quién la paga) con las tarifas reales de cada pasarela | D12: Alta | E12: Pendiente | F12: Dueño | G12: Tarifas confirmadas | I12: Por defecto 6/5/4,5/4 % y mínimo $1.000; ver hoja Comision y ANALISIS_COMISION.md | J12: ANALISIS_COMISION.md
A13: T-012 | B13: Negocio | C13: Decidir qué promete "identidad verificada" (cambiar el texto o llegar a vincular con la cédula) | D13: Alta | E13: Pendiente | F13: Dueño | I13: Video + cédula revisada por una persona ya implementado como vía sin biometría | J13: docs/adr/0006
A14: T-013 | B14: Corfo | C14: Elegir programa Corfo y leer las bases oficiales vigentes | D14: Alta | E14: Pendiente | F14: Dueño | J14: ESTADO_Y_PROXIMOS_PASOS.md
A15: T-014 | B15: Corfo | C15: Encuesta con personas reales (Google Forms) para datos de necesidad de mercado | D15: Media | E15: Pendiente | F15: Dueño | J15: ESTADO_Y_PROXIMOS_PASOS.md
A16: T-015 | B16: Corfo | C16: Presupuesto con supuestos escritos (hoja Presupuesto) | D16: Media | E16: Pendiente | F16: Dueño | J16: hoja Presupuesto
A17: T-016 | B17: Corfo | C17: Definir equipo y asesores con roles | D17: Media | E17: Pendiente | F17: Dueño
A18: T-017 | B18: Corfo | C18: Grabar el video demo del README | D18: Media | E18: Pendiente | F18: Dueño | J18: README.md
A19: T-018 | B19: Pruebas | C19: Recorrido manual como cliente y como proveedor (hoja Pruebas): eliminar cuenta, cancelar/rechazar, cerrar sesiones, verificación con video | D19: Alta | E19: Pendiente | F19: Dueño | I19: Los tests pasan, pero nadie los ha visto en pantalla | J19: hoja Pruebas
A20: T-019 | B20: Pruebas | C20: Probar un pago de punta a punta con Flow y con Mercado Pago en sandbox | D20: Alta | E20: Bloqueado | F20: Dueño | G20: Cuentas sandbox | I20: Solo probados con mocks | J20: ESTADO_Y_PROXIMOS_PASOS.md
A21: T-020 | B21: Desarrollo | C21: Ajustar Flow y Mercado Pago según lo que falle en el sandbox real | D21: Alta | E21: Bloqueado | F21: Claude | G21: Cuentas sandbox | I21: Mirar primero FlowService._firmar y crear_preferencia | J21: pagos.py
A22: T-021 | B22: Desarrollo | C22: Verificar el correo al registrarse (reusar CodigoSeguridad) | D22: Media | E22: Bloqueado | F22: Claude | G22: SMTP real | J22: BACKLOG.md
A23: T-022 | B23: Desarrollo | C23: Más avisos por correo: acceso nuevo a la cuenta, verificación por vencer | D23: Media | E23: Bloqueado | F23: Claude | G23: SMTP real | J23: docs/adr/0007
A24: T-023 | B24: Desarrollo | C24: Prueba real del dispositivo en la verificación nativa (llave que firma un desafío, o Play Integrity/App Attest) | D24: Media | E24: Pendiente | F24: Claude | G24: Decidir opción | I24: Hoy solo reconfirma a quien ya tiene documento aprobado | J24: docs/adr/0006
A25: T-024 | B25: Desarrollo | C25: Ocultar del catálogo a proveedores con la verificación vencida (con aviso previo) | D25: Media | E25: Pendiente | F25: Claude | G25: Decisión de producto | I25: Confirmar trabajos ya se bloquea | J25: docs/adr/0006
A26: T-025 | B26: Desarrollo | C26: Reembolsos automáticos por la API de cada pasarela, parciales y contracargos | D26: Media | E26: Pendiente | F26: Claude | G26: Pasarelas elegidas | I26: Hoy se registran y se devuelven a mano | J26: PLAN_FLUJO_DE_DINERO.md
A27: T-026 | B27: Desarrollo | C27: Pagos al proveedor (payouts o split) y libro de movimientos | D27: Alta | E27: Pendiente | F27: Claude | G27: Decisión de recaudación + abogado | J27: PLAN_FLUJO_DE_DINERO.md
A28: T-027 | B28: Desarrollo | C28: Documentos tributarios (boleta/factura, notas de crédito) | D28: Media | E28: Pendiente | F28: Claude | G28: Contador | J28: PLAN_FLUJO_DE_DINERO.md
A29: T-028 | B29: Desarrollo | C29: Pedir código por correo también al cambiar correo/teléfono y al eliminar la cuenta | D29: Media | E29: Pendiente | F29: Claude | I29: El modelo CodigoSeguridad ya existe | J29: BACKLOG.md
A30: T-029 | B30: Desarrollo | C30: Retención reforzada de casos marcados ("legal hold") para evidencia | D30: Media | E30: Bloqueado | F30: Claude | G30: Abogado | I30: Hoy un chat cerrado se borra a los 90 días | J30: docs/adr/0007
A31: T-030 | B31: Calidad | C31: Tests e2e de los flujos nuevos (cancelar/rechazar, eliminar cuenta, cerrar sesiones, reembolso, verificación con video) | D31: Media | E31: Pendiente | F31: Claude | I31: Cuidar de no romper los datos demo | J31: e2e/
A32: T-031 | B32: Calidad | C32: Deuda de lint del frontend (105 errores prefer-inject) y correr lint en el CI | D32: Baja | E32: Pendiente | F32: Claude | I32: Cambio mecánico, grande | J32: CLAUDE.md
A33: T-032 | B33: Calidad | C33: Geocodificar más comunas (hoy solo 9 de la RM) | D33: Baja | E33: Pendiente | F33: Claude | J33: BACKLOG.md
A34: T-033 | B34: Producto | C34: Fintoc como medio de pago adicional (transferencias, llaves de test) | D34: Baja | E34: Pendiente | F34: Claude | I34: Evaluado, no integrado | J34: ESTADO_Y_PROXIMOS_PASOS.md
A35: T-034 | B35: Producto | C35: Mostrar el precio con la comisión incluida en el catálogo (hoy muestra el precio sin comisión) | D35: Baja | E35: Pendiente | F35: Claude | G35: Decisión del dueño | J35: ANALISIS_COMISION.md
A36: T-035 | B36: Corfo | C36: Elegir al beneficiario (persona natural) y acordar el reparto de la futura sociedad entre los tres antes de postular | D36: Alta | E36: Pendiente | F36: Dueño | I36: Si se aprueba hay que constituir la sociedad: el beneficiario debe tener participación mayoritaria y cada integrante al menos 5 % | J36: docs/corfo/README.md
A37: T-036 | B37: Corfo | C37: Buscar la Entidad Patrocinadora (nómina de Semilla Inicia de la región) y la red de mentores; preguntar a INACAP | D37: Alta | E37: Pendiente | F37: Dueño | I37: Ambas son obligatorias en las bases | J37: docs/corfo/README.md
A38: T-037 | B38: Corfo | C38: Estudio de competencia chilena y tamaño de mercado con fuentes citables (la tesis solo compara con plataformas extranjeras) | D38: Alta | E38: Pendiente | F38: Dueño | I38: Pesa en Innovación (40 %) y Escalabilidad (30 %) | J38: docs/corfo/DE_LA_TESIS_A_LA_POSTULACION.md
A39: T-038 | B39: Corfo | C39: Completar el borrador de postulación: equipo, horas, ODS, sostenibilidad, metas de piloto | D39: Alta | E39: Pendiente | F39: Dueño | I39: Claude puede ayudar a redactar con tus datos | J39: docs/corfo/BORRADOR_POSTULACION.md
A40: T-039 | B40: Corfo | C40: Grabar el video de máximo 40 segundos (alojado con fecha de carga) y probar que abre sin clave | D40: Alta | E40: Pendiente | F40: Dueño | I40: Si no abre, la postulación no se evalúa | J40: docs/corfo/BORRADOR_POSTULACION.md
...

Sheet Planner
A1: Título | B1: Bucket | C1: Progreso | D1: Prioridad | E1: Fecha límite | F1: Asignado a | G1: Notas
A2: =Tareas!C2 | B2: =Tareas!B2 | C2: =IF(Tareas!E2="Hecho","Completada",IF(Tareas!E2="En curso","En curso","No iniciada")) | D2: =IF(Tareas!D2="Alta","Importante",IF(Tareas!D2="Media","Media","Baja")) | E2: =IF(Tareas!H2="","",Tareas!H2) | F2: =Tareas!F2 | G2: =Tareas!I2
A3: =Tareas!C3 | B3: =Tareas!B3 | C3: =IF(Tareas!E3="Hecho","Completada",IF(Tareas!E3="En curso","En curso","No iniciada")) | D3: =IF(Tareas!D3="Alta","Importante",IF(Tareas!D3="Media","Media","Baja")) | E3: =IF(Tareas!H3="","",Tareas!H3) | F3: =Tareas!F3 | G3: =Tareas!I3
A4: =Tareas!C4 | B4: =Tareas!B4 | C4: =IF(Tareas!E4="Hecho","Completada",IF(Tareas!E4="En curso","En curso","No iniciada")) | D4: =IF(Tareas!D4="Alta","Importante",IF(Tareas!D4="Media","Media","Baja")) | E4: =IF(Tareas!H4="","",Tareas!H4) | F4: =Tareas!F4 | G4: =Tareas!I4
A5: =Tareas!C5 | B5: =Tareas!B5 | C5: =IF(Tareas!E5="Hecho","Completada",IF(Tareas!E5="En curso","En curso","No iniciada")) | D5: =IF(Tareas!D5="Alta","Importante",IF(Tareas!D5="Media","Media","Baja")) | E5: =IF(Tareas!H5="","",Tareas!H5) | F5: =Tareas!F5 | G5: =Tareas!I5
A6: =Tareas!C6 | B6: =Tareas!B6 | C6: =IF(Tareas!E6="Hecho","Completada",IF(Tareas!E6="En curso","En curso","No iniciada")) | D6: =IF(Tareas!D6="Alta","Importante",IF(Tareas!D6="Media","Media","Baja")) | E6: =IF(Tareas!H6="","",Tareas!H6) | F6: =Tareas!F6 | G6: =Tareas!I6
A7: =Tareas!C7 | B7: =Tareas!B7 | C7: =IF(Tareas!E7="Hecho","Completada",IF(Tareas!E7="En curso","En curso","No iniciada")) | D7: =IF(Tareas!D7="Alta","Importante",IF(Tareas!D7="Media","Media","Baja")) | E7: =IF(Tareas!H7="","",Tareas!H7) | F7: =Tareas!F7 | G7: =Tareas!I7
A8: =Tareas!C8 | B8: =Tareas!B8 | C8: =IF(Tareas!E8="Hecho","Completada",IF(Tareas!E8="En curso","En curso","No iniciada")) | D8: =IF(Tareas!D8="Alta","Importante",IF(Tareas!D8="Media","Media","Baja")) | E8: =IF(Tareas!H8="","",Tareas!H8) | F8: =Tareas!F8 | G8: =Tareas!I8
A9: =Tareas!C9 | B9: =Tareas!B9 | C9: =IF(Tareas!E9="Hecho","Completada",IF(Tareas!E9="En curso","En curso","No iniciada")) | D9: =IF(Tareas!D9="Alta","Importante",IF(Tareas!D9="Media","Media","Baja")) | E9: =IF(Tareas!H9="","",Tareas!H9) | F9: =Tareas!F9 | G9: =Tareas!I9
A10: =Tareas!C10 | B10: =Tareas!B10 | C10: =IF(Tareas!E10="Hecho","Completada",IF(Tareas!E10="En curso","En curso","No iniciada")) | D10: =IF(Tareas!D10="Alta","Importante",IF(Tareas!D10="Media","Media","Baja")) | E10: =IF(Tareas!H10="","",Tareas!H10) | F10: =Tareas!F10 | G10: =Tareas!I10
A11: =Tareas!C11 | B11: =Tareas!B11 | C11: =IF(Tareas!E11="Hecho","Completada",IF(Tareas!E11="En curso","En curso","No iniciada")) | D11: =IF(Tareas!D11="Alta","Importante",IF(Tareas!D11="Media","Media","Baja")) | E11: =IF(Tareas!H11="","",Tareas!H11) | F11: =Tareas!F11 | G11: =Tareas!I11
A12: =Tareas!C12 | B12: =Tareas!B12 | C12: =IF(Tareas!E12="Hecho","Completada",IF(Tareas!E12="En curso","En curso","No iniciada")) | D12: =IF(Tareas!D12="Alta","Importante",IF(Tareas!D12="Media","Media","Baja")) | E12: =IF(Tareas!H12="","",Tareas!H12) | F12: =Tareas!F12 | G12: =Tareas!I12
A13: =Tareas!C13 | B13: =Tareas!B13 | C13: =IF(Tareas!E13="Hecho","Completada",IF(Tareas!E13="En curso","En curso","No iniciada")) | D13: =IF(Tareas!D13="Alta","Importante",IF(Tareas!D13="Media","Media","Baja")) | E13: =IF(Tareas!H13="","",Tareas!H13) | F13: =Tareas!F13 | G13: =Tareas!I13
... A58: =Tareas!C58 | B58: =Tareas!B58 | C58: =IF(Tareas!E58="Hecho","Completada",IF(Tareas!E58="En curso","En curso","No iniciada")) | D58: =IF(Tareas!D58="Alta","Importante",IF(Tareas!D58="Media","Media","Baja")) | E58: =IF(Tareas!H58="","",Tareas!H58) | F58: =Tareas!F58 | G58: =Tareas!I58
A60: Se llena sola desde la hoja Tareas (filas 2 a 58). Si agregas tareas, copia las fórmulas hacia abajo.

Sheet Cambios
A1: Fecha | B1: Commit | C1: Área | D1: Resumen | E1: Notas
A2: 2026-10-10 | B2: 37c36e2 | C2: Docs | D2: docs: reconocimiento inicial y ajustes de plan (fase 0)
A3: 2026-10-10 | B3: 444823b | C3: Docs | D3: fase 1 (parcial): endurece admin/CORS/logs, declara requests y documenta plan maestro
A4: 2026-10-10 | B4: b037403 | C4: Código | D4: fase 1: borradores de registro de tratamiento y encargados; actualiza estado del plan
A5: 2026-10-10 | B5: 88bcbcd | C5: Código | D5: fase 1: fotos de resenas a almacenamiento privado, EIPD borrador
A6: 2026-10-10 | B6: b16b5fb | C6: Seguridad | D6: docs: registra decisiones de producto sobre verificacion (nativa principal, via alternativa con MFA)
A7: 2026-10-10 | B7: b8100d3 | C7: Código | D7: fase 2: consentimiento biometrico versionado (modelo, gating, revocacion, UI Django e Ionic)
A8: 2026-10-10 | B8: 53216aa | C8: Código | D8: fase 2: cifra encoding_facial en reposo y agrega enforcement de identidad (apagado por defecto)
A9: 2026-10-10 | B9: 7c4df38 | C9: Seguridad | D9: fase 3: derechos del titular (mis-datos, eliminar-cuenta por anonimizacion) con UI en Ionic
A10: 2026-10-10 | B10: 7b0cea7 | C10: Código | D10: fase 3: retencion automatizable (purgar_datos_vencidos, mantenimiento_retencion; borra fotos de chats)
A11: 2026-10-10 | B11: a0f2526 | C11: Docs | D11: fase 2: via alternativa de identidad sin biometria (advertencia + codigo por correo + documento revisado), API, admin e Ionic
A12: 2026-10-11 | B12: 33741a0 | C12: Docs | D12: docs: estado del proyecto y proximos pasos (retoma, demo de Render caido)
A13: 2026-10-12 | B13: c5c2ed3 | C13: Docs | D13: docs: reordena la documentacion (indice, archivo historico, CLAUDE.md condensado)
... A48: 2026-10-16 | B48: c687bee | C48: Pagos | D48: Agrega comisión por tramos, verificación con video y tablero de seguimiento
A49: 2026-10-23 | B49: e20bfac | C49: Código | D49: Agrega medición de impacto: preguntas voluntarias, tipo de servicio y reporte agregado | E49: Bloque 1 (T-054)
A50: 2026-10-23 | B50: b525d74 | C50: Código | D50: Agrega la calculadora gratuita de valorización con boleta de honorarios | E50: Bloque 2 (T-055)
A51: 2026-10-23 | B51: 32e5bea | C51: Código | D51: Agrega el registro del folio de la boleta de honorarios (fase 1, sin SII) | E51: Bloque 3 (T-056)
A52: 2026-10-23 | B52: 611ed94 | C52: Código | D52: Destaca la vía sin historial (cédula y video) y corrige el aviso de fotos del rostro | E52: Bloque 4 (T-057)

Sheet Decisiones
A1: ID | B1: Fecha | C1: Decisión | D1: Quién | E1: Estado | F1: Referencia
A2: D-001 | B2: 2026-10-11 | C2: Biometría nativa como vía principal; rostro en servidor como secundaria; vía sin biometría como respaldo | D2: Dueño | E2: Aprobada | F2: docs/adr/0001
A3: D-002 | B3: 2026-10-12 | C3: El Moderador puede aprobar la verificación sin biometría (queda quién y cuándo) | D3: Dueño | E3: Aprobada | F3: plan-ajustes.md
A4: D-003 | B4: 2026-10-12 | C4: Commits en español, trabajo directo en master, tags en los hitos | D4: Dueño | E4: Aprobada | F4: plan-ajustes.md
A5: D-004 | B5: 2026-10-12 | C5: Vector facial cifrado en reposo; verificación vigente 180 días | D5: Dueño | E5: Aprobada | F5: docs/adr/0002, 0003
A6: D-005 | B6: 2026-10-13 | C6: Postula a Corfo como persona natural; ingresos por comisión sobre cada servicio pagado | D6: Dueño | E6: Aprobada | F6: ESTADO_Y_PROXIMOS_PASOS.md
A7: D-006 | B7: 2026-10-15 | C7: Eliminar la cuenta bloquea y espera 15 días antes de anonimizar (por quejas o problemas entre las partes) | D7: Dueño | E7: Aprobada | F7: docs/adr/0007
A8: D-007 | B8: 2026-10-15 | C8: Las solicitudes sin respuesta expiran (7 días, ajustable) y se avisa por correo a ambas partes | D8: Dueño | E8: Aprobada | F8: docs/adr/0007
A9: D-008 | B9: 2026-10-15 | C9: Verificación nativa solo reconfirma a quien ya tiene documento aprobado (opción c) | D9: Dueño | E9: Aprobada | F9: docs/adr/0006
A10: D-009 | B10: 2026-10-15 | C10: Cerrar sesión en todos los dispositivos exige un código enviado al correo | D10: Dueño | E10: Aprobada | F10: ESTADO_Y_PROXIMOS_PASOS.md
A11: D-010 | B11: 2026-10-16 | C11: Comisión por tramos que paga el cliente encima del precio; valores por defecto 6/5/4,5/4 % con mínimo $1.000 (los de 5/4/3,5/3 % pierden plata con tarjeta) | D11: Claude (propuesta) | E11: Propuesta | F11: ANALISIS_COMISION.md
A12: D-011 | B12: 2026-10-16 | C12: Verificación sin biometría con video corto + cédula revisados por un moderador; el video se borra al resolver (30 días si nadie lo resuelve) | D12: Dueño / Claude | E12: Aprobada | F12: docs/adr/0006
A13: D-012 | B13: 2026-10-16 | C13: Flow y Mercado Pago como medios de pago adicionales (sandbox gratis); Khipu sigue sin sandbox | D13: Dueño | E13: Aprobada | F13: ESTADO_Y_PROXIMOS_PASOS.md
A14: D-013 | C14: Qué evidencia se conserva para la policía y por cuánto tiempo | D14: Dueño + abogado | E14: Pendiente | F14: docs/adr/0007
A15: D-014 | C15: Opción de prueba real del dispositivo para la verificación nativa (a, a-lite, b) | D15: Dueño | E15: Pendiente | F15: docs/adr/0006
A16: D-015 | C16: Recaudar y transferir, Webpay Mall o split de pagos | D16: Dueño + abogado | E16: Pendiente | F16: PLAN_FLUJO_DE_DINERO.md
A17: D-016 | B17: 2026-10-23 | C17: Encuadre de la postulación: inclusión laboral y formalización, no antifraude | D17: Dueño | E17: Aprobada | F17: docs/corfo/RESUMEN_PARA_PLANIFICACION.md
A18: D-017 | B18: 2026-10-23 | C18: Economía circular = reparar y mantener en vez de reemplazar; el ingreso que queda en la comuna se reporta aparte como "economía local" | D18: Dueño | E18: Aprobada | F18: docs/corfo/RESUMEN_PARA_PLANIFICACION.md
A19: D-018 | B19: 2026-10-23 | C19: Calculadora de valorización gratuita y abierta sin cuenta | D19: Dueño | E19: Aprobada | F19: Bloque 2
A20: D-019 | B20: 2026-10-23 | C20: Boleta fase 1: el proveedor emite en sii.cl y KeyServ registra el folio; integración directa con el SII queda para después | D20: Dueño | E20: Aprobada | F20: Bloque 3
A21: D-020 | B21: 2026-10-23 | C21: ODS declarados: 8 (principal), 10 y 12. No se declaran el 5 ni el 16 | D21: Dueño | E21: Aprobada | F21: docs/corfo/BORRADOR_POSTULACION.md
A22: D-021 | B22: 2026-10-23 | C22: Medición de impacto: datos voluntarios (situación laboral previa, género), tipo de servicio y pregunta de reemplazo; reporte solo agregado con supresión de grupos < 5 y sin cuentas demo | D22: Claude (técnica) / Dueño (estrategia) | E22: Aprobada | F22: docs/adr/0008
A23: D-022 | B23: 2026-10-23 | C23: Calculadora de valorización: el cálculo vive en el servidor (usa la comisión real), pesos enteros con boleta redondeada hacia arriba, exportación PDF/xlsx en el servidor, plantillas por cuenta, hoja de presupuesto extendida, contador anónimo con hash mensual | D23: Claude (técnica) / Dueño (estrategia) | E23: Aprobada | F23: docs/adr/0009
A24: D-023 | B24: 2026-10-23 | C24: Boleta fase 1: el proveedor registra el folio de un trabajo pagado (uno por contratación, no repetido por proveedor, una sola primera boleta); KeyServ no emite ni verifica; el folio se conserva al anonimizar la cuenta | D24: Claude (técnica) / Dueño (estrategia) | E24: Aprobada | F24: docs/adr/0010
A25: D-024 | B25: 2026-10-23 | C25: Vía sin historial: destacar la cédula + video en portada y registro, diciendo que es una revisión humana (no una consulta al Registro Civil); corregir el aviso "0 fotos de tu rostro guardadas" | D25: Claude (copy) / Dueño (estrategia) | E25: Aprobada | F25: docs/adr/0006 (actualización 2026-10-23)

Sheet Pendientes_dueño
A1: Tema | B1: Qué hay que hacer | C1: Listo | D1: Fecha | E1: Notas
A2: SMTP real | B2: Crear la cuenta que enviará los correos y cargar SMTP_HOST/PORT/USER/PASSWORD y DJANGO_DEFAULT_FROM_EMAIL en .env y en Render | C2: No | E2: Sin esto no llega ningún código ni aviso
A3: Sandbox Flow | B3: Cuenta en sandbox.flow.cl; copiar ApiKey y SecretKey | C3: No | E3: Escribirlas tú, nunca en el chat
A4: Sandbox Mercado Pago | B4: Aplicación en el panel de desarrolladores de Mercado Pago Chile; copiar el Access Token de prueba | C4: No
A5: Probar pagos | B5: Pago de punta a punta con cada pasarela (Mercado Pago contra Render) | C5: No | E5: Avisar el error si falla
A6: Claves de producción | B6: DJANGO_SECRET_KEY, JWT_SECRET, BIOMETRIC_ENCRYPTION_KEYS en Render | C6: No | E6: Mirar las advertencias keyserv.W001-W003 en el log del deploy
A7: Comisión | B7: Elegir tramos finales con las tarifas confirmadas de cada pasarela | C7: No | E7: Hoja Comision
A8: Recorrido manual | B8: Probar en pantalla: eliminar cuenta, cancelar/rechazar, cerrar sesiones, reembolso, verificación con video con un moderador | C8: No | E8: Hoja Pruebas
A9: Moderador | B9: Crear la cuenta de moderador real que revisará videos y cédulas (grupo Moderador) | C9: No | E9: manage.py configurar_grupo_moderador
A10: Abogado | B10: Consentimiento biométrico y de video, EIPD, evidencia para investigaciones, Términos y Condiciones, custodia de fondos | C10: No | E10: ADR 0006, 0007 y plan de dinero
A11: Contador | B11: IVA de la comisión, boletas/facturas, inicio de actividades | C11: No | E11: Plan de dinero §4
A12: Keystore Android | B12: Respaldar keyserv-release.keystore y keystore.properties fuera del repo | C12: No
A13: NVIDIA | B13: Revisar si el plan gratuito permite producción y declarar el envío de texto fuera de Chile | C13: No
A14: Corfo | B14: Programa, bases, encuesta Google Forms, presupuesto, equipo, video demo | C14: No
A15: Abogado: medición de impacto | B15: Revisar la finalidad escrita en el registro y en la política, la base de licitud (consentimiento voluntario y revocable), si situación laboral previa y género son dato sensible bajo la Ley 21.719 y el plazo de conservación | C15: No | E15: ADR 0008; registro-actividades-tratamiento.md
A16: Contador: boleta de honorarios en la calculadora | B16: Confirmar la retención vigente (la calculadora usa 16 % para 2027, editable con CALCULADORA_RETENCION_BOLETA) y cómo van los materiales dentro de una boleta de honorarios | C16: No | E16: ADR 0009
A17: Abogado: contador anónimo de la calculadora | B17: Confirmar si el identificador aleatorio del navegador (hash mensual, sin IP ni cuenta) cuenta como dato personal y si basta con lo declarado en la política | C17: No | E17: ADR 0009; registro-actividades-tratamiento.md
A18: Contador/abogado: boleta fase 2 | B18: Antes de verificar el folio con el SII o emitir boletas desde KeyServ: tratamiento tributario de la comisión, si hace falta ser emisor autorizado y qué integración corresponde | C18: No | E18: ADR 0010; PLAN_FLUJO_DE_DINERO.md §4

Sheet Riesgos
A1: N° | B1: Riesgo | C1: Probabilidad (1-5) | D1: Impacto (1-5) | E1: Puntaje | F1: Mitigación | G1: Estado
A2: 1 | B2: Pagos nunca probados en sandbox real (Flow, Mercado Pago, Khipu) | C2: 4 | D2: 3 | E2: =C2*D2 | F2: Probar con cuentas de sandbox antes de mostrar; hasta entonces no se ofrecen (solo aparecen si hay claves) | G2: Abierto
A3: 2 | B3: Correos no llegan en el demo (sin SMTP) | C3: 5 | D3: 3 | E3: =C3*D3 | F3: Configurar SMTP real; probar con probar_correo | G3: Abierto
A4: 3 | B4: "Identidad verificada" promete más de lo que prueba | C4: 4 | D4: 5 | E4: =C4*D4 | F4: Verificación con video + cédula revisada por una persona; decidir el texto; ADR 0006 | G4: Mitigando
A5: 4 | B5: Claves de producción con valores por defecto | C5: 3 | D5: 5 | E5: =C5*D5 | F5: Fijarlas en Render; los avisos W001-W003 lo recuerdan en cada deploy | G5: Abierto
A6: 5 | B6: Comisión menor al costo de la pasarela (pérdida con tarjeta en montos altos) | C6: 4 | D6: 4 | E6: =C6*D6 | F6: Tramos por defecto 6/5/4,5/4 %; promover transferencias; hoja Comision | G6: Mitigando
A7: 6 | B7: Custodia de fondos de terceros sin encuadre legal (Ley Fintech) | C7: 3 | D7: 5 | E7: =C7*D7 | F7: Consulta a un abogado antes de cobrar dinero real | G7: Abierto
A8: 7 | B8: Video de verificación es un dato sensible | C8: 3 | D8: 5 | E8: =C8*D8 | F8: Consentimiento explícito, almacenamiento privado, borrado al resolver y a los 30 días, solo staff; revisión legal | G8: Mitigando
A9: 8 | B9: Un solo operador para verificaciones, derechos del titular y reembolsos | C9: 4 | D9: 3 | E9: =C9*D9 | F9: Panel con KPI; documentar procedimientos; sumar moderadores | G9: Abierto
A10: 9 | B10: Pérdida del keystore de Android | C10: 2 | D10: 5 | E10: =C10*D10 | F10: Respaldo fuera del repo | G10: Abierto
A11: 10 | B11: Evidencia para la policía se borra por la retención (chats a 90 días) | C11: 3 | D11: 4 | E11: =C11*D11 | F11: Decidir con abogado un "legal hold"; ADR 0007 | G11: Abierto
A12: 11 | B12: Complejidad creciente (dos frontends, muchas piezas) para una sola persona | C12: 4 | D12: 3 | E12: =C12*D12 | F12: Consolidar antes de sumar funciones; retirar plantillas Django por área | G12: Abierto
B14: Puntaje = probabilidad x impacto (rojo desde 15, amarillo desde 8).

Sheet Comision
A1: Calculadora de comisión y margen por transacción
A2: La comisión se cobra ENCIMA del precio: el cliente paga servicio + comisión, el proveedor recibe el servicio. Margen = comisión sin IVA − costo de la pasarela. Cifras en CLP. Las tarifas son de terceros (oct. 2026): confírmalas.
A4: Comisión mínima (CLP) | B4: 1000
A5: IVA | B5: 0.19
A6: ¿IVA de la pasarela recuperable? (1 = sí, 0 = no) | B6: 1
A8: Tramo: hasta (CLP) | B8: Comisión (%)
A9: 50000 | B9: 0.06
A10: 200000 | B10: 0.05
A11: 500000 | B11: 0.045
A12: Sobre el tramo anterior | B12: 0.04
A14: Medio de pago | B14: % sobre el total | C14: Fijo (CLP)
A15: Webpay débito/prepago | B15: 0.0175 | C15: 0
A16: Webpay crédito | B16: 0.0235 | C16: 0
A17: Flow tarjeta | B17: 0.0289 | C17: 0
A18: Transferencia (Flow/Khipu) | B18: 0.0099 | C18: 100
A19: Fuente de las tarifas: guías de terceros (Digitalízame, Comocobro, guía de Flow), octubre 2026; sin IVA. Confirmar con cada pasarela.
A21: Margen por transacción (CLP)
A22: Precio del servicio | B22: % aplicado | C22: Comisión | D22: Total que paga el cliente | E22: =A15 | F22: =A16 | G22: =A17 | H22: =A18
A23: 20000 | B23: =IF(A23<=$A$9,$B$9,IF(A23<=$A$10,$B$10,IF(A23<=$A$11,$B$11,$B$12))) | C23: =MAX(ROUND(A23*B23,0),$B$4) | D23: =A23+C23 | E23: =C23/(1+$B$5)-(D23*$B$15+$C$15)*IF($B$6=1,1,1+$B$5) | F23: =C23/(1+$B$5)-(D23*$B$16+$C$16)*IF($B$6=1,1,1+$B$5) | G23: =C23/(1+$B$5)-(D23*$B$17+$C$17)*IF($B$6=1,1,1+$B$5) | H23: =C23/(1+$B$5)-(D23*$B$18+$C$18)*IF($B$6=1,1,1+$B$5)
A24: 50000 | B24: =IF(A24<=$A$9,$B$9,IF(A24<=$A$10,$B$10,IF(A24<=$A$11,$B$11,$B$12))) | C24: =MAX(ROUND(A24*B24,0),$B$4) | D24: =A24+C24 | E24: =C24/(1+$B$5)-(D24*$B$15+$C$15)*IF($B$6=1,1,1+$B$5) | F24: =C24/(1+$B$5)-(D24*$B$16+$C$16)*IF($B$6=1,1,1+$B$5) | G24: =C24/(1+$B$5)-(D24*$B$17+$C$17)*IF($B$6=1,1,1+$B$5) | H24: =C24/(1+$B$5)-(D24*$B$18+$C$18)*IF($B$6=1,1,1+$B$5)
A25: 100000 | B25: =IF(A25<=$A$9,$B$9,IF(A25<=$A$10,$B$10,IF(A25<=$A$11,$B$11,$B$12))) | C25: =MAX(ROUND(A25*B25,0),$B$4) | D25: =A25+C25 | E25: =C25/(1+$B$5)-(D25*$B$15+$C$15)*IF($B$6=1,1,1+$B$5) | F25: =C25/(1+$B$5)-(D25*$B$16+$C$16)*IF($B$6=1,1,1+$B$5) | G25: =C25/(1+$B$5)-(D25*$B$17+$C$17)*IF($B$6=1,1,1+$B$5) | H25: =C25/(1+$B$5)-(D25*$B$18+$C$18)*IF($B$6=1,1,1+$B$5)
A26: 300000 | B26: =IF(A26<=$A$9,$B$9,IF(A26<=$A$10,$B$10,IF(A26<=$A$11,$B$11,$B$12))) | C26: =MAX(ROUND(A26*B26,0),$B$4) | D26: =A26+C26 | E26: =C26/(1+$B$5)-(D26*$B$15+$C$15)*IF($B$6=1,1,1+$B$5) | F26: =C26/(1+$B$5)-(D26*$B$16+$C$16)*IF($B$6=1,1,1+$B$5) | G26: =C26/(1+$B$5)-(D26*$B$17+$C$17)*IF($B$6=1,1,1+$B$5) | H26: =C26/(1+$B$5)-(D26*$B$18+$C$18)*IF($B$6=1,1,1+$B$5)
A27: 600000 | B27: =IF(A27<=$A$9,$B$9,IF(A27<=$A$10,$B$10,IF(A27<=$A$11,$B$11,$B$12))) | C27: =MAX(ROUND(A27*B27,0),$B$4) | D27: =A27+C27 | E27: =C27/(1+$B$5)-(D27*$B$15+$C$15)*IF($B$6=1,1,1+$B$5) | F27: =C27/(1+$B$5)-(D27*$B$16+$C$16)*IF($B$6=1,1,1+$B$5) | G27: =C27/(1+$B$5)-(D27*$B$17+$C$17)*IF($B$6=1,1,1+$B$5) | H27: =C27/(1+$B$5)-(D27*$B$18+$C$18)*IF($B$6=1,1,1+$B$5)
A28: 1000000 | B28: =IF(A28<=$A$9,$B$9,IF(A28<=$A$10,$B$10,IF(A28<=$A$11,$B$11,$B$12))) | C28: =MAX(ROUND(A28*B28,0),$B$4) | D28: =A28+C28 | E28: =C28/(1+$B$5)-(D28*$B$15+$C$15)*IF($B$6=1,1,1+$B$5) | F28: =C28/(1+$B$5)-(D28*$B$16+$C$16)*IF($B$6=1,1,1+$B$5) | G28: =C28/(1+$B$5)-(D28*$B$17+$C$17)*IF($B$6=1,1,1+$B$5) | H28: =C28/(1+$B$5)-(D28*$B$18+$C$18)*IF($B$6=1,1,1+$B$5)
A30: Rojo = KeyServ pierde plata en esa combinación. Es margen bruto: no incluye hosting, revisión de identidad, soporte ni impuesto a la renta. Cambia los valores azules para probar otros tramos.
A31: Para aplicar tramos distintos en el sistema: variable de entorno COMISION_TRAMOS (JSON) y COMISION_MINIMA; ver docs/ANALISIS_COMISION.md.

Sheet Presupuesto
A1: Presupuesto con supuestos (para Corfo)
A2: Completa las celdas amarillas. Escribe de dónde sale cada número en la última columna: Corfo pide supuestos escritos.
A3: Tipo de cambio USD → CLP | F3: Completa con el valor del día; las filas en USD se convierten con este número.
A5: Concepto | B5: Moneda | C5: Monto unitario | D5: Cantidad (meses o unidades) | E5: Total (CLP) | F5: Supuesto / fuente
A6: Cuenta de desarrollador de Google Play (pago único) | B6: USD | C6: 25 | D6: 1 | E6: =IF(C6="","",C6*D6*IF(B6="USD",$B$3,1)) | F6: Ejemplo ya completado: tarifa de registro de Google Play Console, pago único.
A7: Cuenta de desarrollador de Apple (anual) | B7: USD | C7: 99 | D7: 1 | E7: =IF(C7="","",C7*D7*IF(B7="USD",$B$3,1)) | F7: Ejemplo ya completado: membresía anual del Apple Developer Program. Solo si se publica en iOS.
A8: Hosting del backend (Render) | B8: CLP | D8: 12 | E8: =IF(C8="","",C8*D8*IF(B8="USD",$B$3,1)) | F8: Completar: plan de pago cuando se salga del plan gratuito.
A9: Base de datos (Neon) | B9: CLP | D9: 12 | E9: =IF(C9="","",C9*D9*IF(B9="USD",$B$3,1)) | F9: Completar
A10: Hosting del frontend (Netlify) | B10: CLP | D10: 12 | E10: =IF(C10="","",C10*D10*IF(B10="USD",$B$3,1)) | F10: Completar
A11: Dominio .cl | B11: CLP | D11: 1 | E11: =IF(C11="","",C11*D11*IF(B11="USD",$B$3,1)) | F11: Completar (renovación anual)
A12: Correo transaccional (SMTP) | B12: CLP | D12: 12 | E12: =IF(C12="","",C12*D12*IF(B12="USD",$B$3,1)) | F12: Completar
A13: Abogado (revisión legal, Términos, EIPD) | B13: CLP | D13: 1 | E13: =IF(C13="","",C13*D13*IF(B13="USD",$B$3,1)) | F13: Completar con cotización
A14: Contador (inicio de actividades, boletas) | B14: CLP | D14: 12 | E14: =IF(C14="","",C14*D14*IF(B14="USD",$B$3,1)) | F14: Completar con cotización
A15: Moderador que revisa verificaciones | B15: CLP | D15: 12 | E15: =IF(C15="","",C15*D15*IF(B15="USD",$B$3,1)) | F15: Completar: horas por mes x valor hora
A16: Desarrollo (horas) | B16: CLP | D16: 1 | E16: =IF(C16="","",C16*D16*IF(B16="USD",$B$3,1)) | F16: Completar
A17: Marketing / captación de proveedores | B17: CLP | D17: 1 | E17: =IF(C17="","",C17*D17*IF(B17="USD",$B$3,1)) | F17: Completar
A18: Total | E18: =SUM(E6:E17)

Sheet Pruebas
A1: ID | B1: Área | C1: Caso | D1: Pasos | E1: Resultado esperado | F1: Resultado | G1: Fecha | H1: Notas
A2: P-001 | B2: Cuenta | C2: Registro con RUT válido, teléfono de 9 dígitos y política aceptada | D2: Completar el formulario de /registro | E2: Cuenta creada; RUT inválido o repetido se rechaza con mensaje claro
A3: P-002 | B3: Cuenta | C3: Login y logout; login con clave mala | D3: Ingresar con clave correcta e incorrecta | E3: Entra con la correcta; la incorrecta da error; tras varios fallos se bloquea
A4: P-003 | B4: Cuenta | C4: Recuperar contraseña | D4: ¿Olvidaste tu contraseña? → correo → enlace | E4: Llega el correo (requiere SMTP) y la clave nueva funciona; las otras sesiones se cierran
A5: P-004 | B5: Cuenta | C5: Cambiar contraseña desde Preferencias | D5: Preferencias → cambiar contraseña | E5: Se cambia, sigues dentro y llega un aviso por correo
A6: P-005 | B6: Cuenta | C6: Cerrar sesión en todos los dispositivos | D6: Preferencias → Seguridad de la sesión → pedir código → ingresarlo | E6: Llega el código; con el correcto se cierran todas las sesiones y vuelves al login
A7: P-006 | B7: Cuenta | C7: Eliminar cuenta con espera de 15 días | D7: Preferencias → Eliminar mi cuenta → contraseña | E7: La cuenta queda bloqueada con fecha de eliminación; sus solicitudes sin confirmar se cancelan; con un trabajo confirmado se rechaza
A8: P-007 | B8: Cuenta | C8: Cancelar la eliminación | D8: Mis datos → desbloquear el tratamiento | E8: Desaparece la fecha de eliminación
A9: P-008 | B9: Catálogo | C9: Buscar, filtrar y abrir un servicio | D9: /catalogo, buscar, abrir un detalle | E9: Resultados correctos y detalle completo
A10: P-009 | B10: Proveedor | C10: Publicar un servicio con fotos | D10: Crear publicación | E10: Queda pendiente de moderación; el moderador la aprueba
A11: P-010 | B11: Contratación | C11: Solicitar un servicio | D11: Cliente → Contratar | E11: Se crea la solicitud; el proveedor recibe aviso (y correo si hay SMTP)
A12: P-011 | B12: Contratación | C12: Rechazar (proveedor) y cancelar (cliente) antes de pagar | D12: Botones en el detalle del trabajo | E12: Estado Cancelada, mensaje en el chat y aviso a la otra parte
A13: P-012 | B13: Contratación | C13: Expiración de solicitudes sin respuesta | D13: manage.py expirar_solicitudes --dias 0 (en local) | E13: Las solicitudes pasan a Cancelada y se avisa a ambos
... A26: P-025 | B26: Móvil | C26: Recorrido completo en el celular (375-390 px) | D26: Login, catálogo, contratar, chat | E26: Todo se ve y funciona sin scroll horizontal
C28: Resumen
C29: OK | D29: =COUNTIF(F2:F26,"OK")
C30: Falla | D30: =COUNTIF(F2:F26,"Falla")
C31: Sin probar | D31: =COUNTA(A2:A26)-D29-D30

Sheet Corfo
A1: N° | B1: Tema | C1: Requisito | D1: Fuente | E1: Estado | F1: Acción | G1: Responsable
A2: 1 | B2: Postulante | C2: Persona natural mayor de 18 años y residente en Chile | D2: Bases 4.1 a) | E2: Por verificar | F2: Elegir al beneficiario entre los tres autores | G2: Dueño
A3: 2 | B3: Postulante | C3: No tener participación en una sociedad que ya ejecute el proyecto | D3: Bases 4.1 a) | E3: Por verificar | F3: No constituir la sociedad antes de postular | G3: Dueño
A4: 3 | B4: Postulante | C4: No figurar en el Registro Nacional de Deudores de Pensiones de Alimentos | D4: Bases 9.1, 13.3 | E4: Por verificar | F4: Cada integrante lo revisa | G4: Dueño
A5: 4 | B5: Postulante | C5: Sin otro proyecto Corfo vigente (más de 2 meses de terminar) ni cofinanciamiento previo del mismo emprendimiento | D5: Bases 4.4 | E5: Por verificar | F5: Confirmar con cada integrante | G5: Dueño
A6: 5 | B6: Postulante | C6: Una sola postulación por persona natural en cada convocatoria | D6: Bases 4.4.2 | E6: Cumple | F6: Postular una vez | G6: Dueño
A7: 6 | B7: Proyecto | C7: Innovación suficiente frente a las soluciones existentes | D7: Bases 2.1, 13.1 | E7: Falta | F7: Estudio de competencia chilena y propuesta de valor | G7: Dueño
A8: 7 | B8: Proyecto | C8: Alcance no exclusivamente local (comunal o provincial no es admisible) | D8: Bases 2.1 c) | E8: Falta | F8: Argumentar plan nacional con inicio en la Región Metropolitana | G8: Dueño
A9: 8 | B9: Proyecto | C9: No tener ingresos por ventas (personas jurídicas) y primera venta durante la ejecución | D9: Bases 3, 4.1 b), 13.3 | E9: Cumple | F9: Mantener el demo sin cobros reales | G9: Dueño
A10: 9 | B10: Proyecto | C10: Objetivo alineado: validación técnica y comercial (no compra de equipos ni consultorías) | D10: Bases 2.1 | E10: Cumple | F10: Redactar el plan de validación | G10: Dueño
A11: 10 | B11: Equipo | C11: Al menos 2 personas (hasta 3 cofundadores) con roles complementarios | D11: Bases 4.2, 9.2 | E11: Por verificar | F11: Confirmar roles y perfil comercial | G11: Dueño
A12: 11 | B12: Equipo | C12: Dedicación horaria comprometida (máx. 40 a 44 h semanales) y verificable | D12: Bases 8 d) | E12: Falta | F12: Completar horas por persona | G12: Dueño
A13: 12 | B13: Participantes | C13: Entidad Patrocinadora de la nómina de Semilla Inicia habilitada para la región | D13: Bases 4.3 | E13: Falta | F13: Buscar y elegir; preguntar a INACAP | G13: Dueño
... A23: 22 | B23: Presupuesto | C23: Incluir la constitución de la sociedad e inicio de actividades (actividad obligatoria si es persona natural) | D23: Bases 7.1 b) | E23: Falta | F23: Cotizar abogado y notaría | G23: Dueño
A24: 23 | B24: Después de aprobar | C24: Contrato con la Entidad Patrocinadora y antecedentes de edad y residencia (15 días) | D24: Bases 13.3, Anexo 1 | E24: Futuro | G24: Dueño
A25: 24 | B25: Después de aprobar | C25: Constituir la persona jurídica: beneficiario con participación mayoritaria; cada integrante con al menos 5 % | D25: Bases 4.4.2 | E25: Futuro | F25: Acordar el reparto desde ya | G25: Dueño
C27: Fuente: bases técnicas de Semilla Inicia (Res. Exenta 1498/2025) y ficha oficial del concurso Biobío 2026. Cada convocatoria puede cambiar los requisitos: leer las bases del llamado exacto.
C29: Cumple | D29: =COUNTIF(E2:E25,"Cumple")
C30: Por verificar | D30: =COUNTIF(E2:E25,"Por verificar")
C31: Borrador | D31: =COUNTIF(E2:E25,"Borrador")
C32: Falta | D32: =COUNTIF(E2:E25,"Falta")
C33: Futuro | D33: =COUNTIF(E2:E25,"Futuro")

Sheet Gantt
A1: Actividad | B1: Responsable | C1: Inicio (mes) | D1: Fin (mes) | E1: 1 | F1: 2 | G1: 3 | H1: 4 | I1: 5 | J1: 6 | K1: 7 | L1: 8 | M1: 9 | N1: 10
A2: Constituir la sociedad e iniciar actividades en el SII | B2: Dueño | C2: 1 | D2: 2
A3: Firmar el contrato con la Entidad Patrocinadora | B3: Dueño | C3: 1 | D3: 1
A4: Definir el modelo de negocios con la mentoría | B4: Todos | C4: 1 | D4: 2
A5: Producción técnica: pasarela real, correo transaccional, T&C, claves | B5: Claude | C5: 1 | D5: 4
A6: Cumplimiento Ley 21.719 y revisión legal | B6: Dueño | C6: 1 | D6: 4
A7: Mentoría (debe iniciar antes del mes 4) | B7: Todos | C7: 2 | D7: 10
A8: Estrategia de operación sostenible (Anexo 3) | B8: Todos | C8: 3 | D8: 6
A9: Piloto con proveedores y clientes reales; validación comercial | B9: Todos | C9: 3 | D9: 9
A10: Primera venta: servicio pagado en la plataforma | B10: Todos | C10: 5 | D10: 8
A11: Medición, ajustes y plan de escalamiento a otras regiones | B11: Todos | C11: 8 | D11: 10
A12: Informe final y rendición | B12: Dueño | C12: 10 | D12: 10
A14: Meses de ejecución desde la firma del convenio (máximo 10, más 2 de prórroga excepcional). Cambia el inicio y el fin (azul) y la barra se mueve sola. Cuando se conozca la fecha de apertura, pasa estas actividades a Planner con fechas reales.
